Microsoft Windows [Version 10.0.19044.2130]
(c) Microsoft Corporation. All rights reserved.

C:\Users\arian>python
Python 3.10.4 (tags/v3.10.4:9d38120, Mar 23 2022, 23:13:41) [MSC v.1929 64 bit (AMD64)] on win32
Type "help", "copyright", "credits" or "license" for more information.
>>> pip install numpy
  File "<stdin>", line 1
    pip install numpy
        ^^^^^^^
SyntaxError: invalid syntax
>>> ^X^Z
  File "<stdin>", line 1
    ↑→
    ^
SyntaxError: invalid syntax
>>> ^Z


C:\Users\arian>pip install numpy
Collecting numpy
  Downloading numpy-1.23.5-cp310-cp310-win_amd64.whl (14.6 MB)
     ---------------------------------------- 14.6/14.6 MB 1.3 MB/s eta 0:00:00
Installing collected packages: numpy
Successfully installed numpy-1.23.5

[notice] A new release of pip available: 22.1.2 -> 22.3.1
[notice] To update, run: python.exe -m pip install --upgrade pip

C:\Users\arian>conda install numpy
'conda' is not recognized as an internal or external command,
operable program or batch file.

C:\Users\arian>py
Python 3.10.4 (tags/v3.10.4:9d38120, Mar 23 2022, 23:13:41) [MSC v.1929 64 bit (AMD64)] on win32
Type "help", "copyright", "credits" or "license" for more information.
>>> import numpy
>>> ^Z


C:\Users\arian>pip install scipy
Collecting scipy
  Downloading scipy-1.9.3-cp310-cp310-win_amd64.whl (40.1 MB)
     ---------------------------------------- 40.1/40.1 MB 1.6 MB/s eta 0:00:00
Requirement already satisfied: numpy<1.26.0,>=1.18.5 in c:\users\arian\appdata\local\programs\python\python310\lib\site-packages (from scipy) (1.23.5)
Installing collected packages: scipy
Successfully installed scipy-1.9.3

[notice] A new release of pip available: 22.1.2 -> 22.3.1
[notice] To update, run: python.exe -m pip install --upgrade pip

C:\Users\arian>pip install pandas
Collecting pandas
  Downloading pandas-1.5.1-cp310-cp310-win_amd64.whl (10.4 MB)
     ------------------- -------------------- 5.1/10.4 MB 1.7 MB/s eta 0:00:04
ERROR: Exception:
Traceback (most recent call last):
  File "C:\Users\arian\AppData\Local\Programs\Python\Python310\lib\site-packages\pip\_vendor\urllib3\response.py", line 435, in _error_catcher
    yield
  File "C:\Users\arian\AppData\Local\Programs\Python\Python310\lib\site-packages\pip\_vendor\urllib3\response.py", line 516, in read
    data = self._fp.read(amt) if not fp_closed else b""
  File "C:\Users\arian\AppData\Local\Programs\Python\Python310\lib\site-packages\pip\_vendor\cachecontrol\filewrapper.py", line 90, in read
    data = self.__fp.read(amt)
  File "C:\Users\arian\AppData\Local\Programs\Python\Python310\lib\http\client.py", line 465, in read
    s = self.fp.read(amt)
  File "C:\Users\arian\AppData\Local\Programs\Python\Python310\lib\socket.py", line 705, in readinto
    return self._sock.recv_into(b)
  File "C:\Users\arian\AppData\Local\Programs\Python\Python310\lib\ssl.py", line 1273, in recv_into
    return self.read(nbytes, buffer)
  File "C:\Users\arian\AppData\Local\Programs\Python\Python310\lib\ssl.py", line 1129, in read
    return self._sslobj.read(len, buffer)
ssl.SSLError: [SSL: DECRYPTION_FAILED_OR_BAD_RECORD_MAC] decryption failed or bad record mac (_ssl.c:2548)

During handling of the above exception, another exception occurred:

Traceback (most recent call last):
  File "C:\Users\arian\AppData\Local\Programs\Python\Python310\lib\site-packages\pip\_internal\cli\base_command.py", line 167, in exc_logging_wrapper
    status = run_func(*args)
  File "C:\Users\arian\AppData\Local\Programs\Python\Python310\lib\site-packages\pip\_internal\cli\req_command.py", line 205, in wrapper
    return func(self, options, args)
  File "C:\Users\arian\AppData\Local\Programs\Python\Python310\lib\site-packages\pip\_internal\commands\install.py", line 341, in run
    requirement_set = resolver.resolve(
  File "C:\Users\arian\AppData\Local\Programs\Python\Python310\lib\site-packages\pip\_internal\resolution\resolvelib\resolver.py", line 94, in resolve
    result = self._result = resolver.resolve(
  File "C:\Users\arian\AppData\Local\Programs\Python\Python310\lib\site-packages\pip\_vendor\resolvelib\resolvers.py", line 481, in resolve
    state = resolution.resolve(requirements, max_rounds=max_rounds)
  File "C:\Users\arian\AppData\Local\Programs\Python\Python310\lib\site-packages\pip\_vendor\resolvelib\resolvers.py", line 348, in resolve
    self._add_to_criteria(self.state.criteria, r, parent=None)
  File "C:\Users\arian\AppData\Local\Programs\Python\Python310\lib\site-packages\pip\_vendor\resolvelib\resolvers.py", line 172, in _add_to_criteria
    if not criterion.candidates:
  File "C:\Users\arian\AppData\Local\Programs\Python\Python310\lib\site-packages\pip\_vendor\resolvelib\structs.py", line 151, in __bool__
    return bool(self._sequence)
  File "C:\Users\arian\AppData\Local\Programs\Python\Python310\lib\site-packages\pip\_internal\resolution\resolvelib\found_candidates.py", line 155, in __bool__
    return any(self)
  File "C:\Users\arian\AppData\Local\Programs\Python\Python310\lib\site-packages\pip\_internal\resolution\resolvelib\found_candidates.py", line 143, in <genexpr>
    return (c for c in iterator if id(c) not in self._incompatible_ids)
  File "C:\Users\arian\AppData\Local\Programs\Python\Python310\lib\site-packages\pip\_internal\resolution\resolvelib\found_candidates.py", line 47, in _iter_built
    candidate = func()
  File "C:\Users\arian\AppData\Local\Programs\Python\Python310\lib\site-packages\pip\_internal\resolution\resolvelib\factory.py", line 215, in _make_candidate_from_link
    self._link_candidate_cache[link] = LinkCandidate(
  File "C:\Users\arian\AppData\Local\Programs\Python\Python310\lib\site-packages\pip\_internal\resolution\resolvelib\candidates.py", line 291, in __init__
    super().__init__(
  File "C:\Users\arian\AppData\Local\Programs\Python\Python310\lib\site-packages\pip\_internal\resolution\resolvelib\candidates.py", line 161, in __init__
    self.dist = self._prepare()
  File "C:\Users\arian\AppData\Local\Programs\Python\Python310\lib\site-packages\pip\_internal\resolution\resolvelib\candidates.py", line 230, in _prepare
    dist = self._prepare_distribution()
  File "C:\Users\arian\AppData\Local\Programs\Python\Python310\lib\site-packages\pip\_internal\resolution\resolvelib\candidates.py", line 302, in _prepare_distribution
    return preparer.prepare_linked_requirement(self._ireq, parallel_builds=True)
  File "C:\Users\arian\AppData\Local\Programs\Python\Python310\lib\site-packages\pip\_internal\operations\prepare.py", line 428, in prepare_linked_requirement
    return self._prepare_linked_requirement(req, parallel_builds)
  File "C:\Users\arian\AppData\Local\Programs\Python\Python310\lib\site-packages\pip\_internal\operations\prepare.py", line 473, in _prepare_linked_requirement
    local_file = unpack_url(
  File "C:\Users\arian\AppData\Local\Programs\Python\Python310\lib\site-packages\pip\_internal\operations\prepare.py", line 155, in unpack_url
    file = get_http_url(
  File "C:\Users\arian\AppData\Local\Programs\Python\Python310\lib\site-packages\pip\_internal\operations\prepare.py", line 96, in get_http_url
    from_path, content_type = download(link, temp_dir.path)
  File "C:\Users\arian\AppData\Local\Programs\Python\Python310\lib\site-packages\pip\_internal\network\download.py", line 146, in __call__
    for chunk in chunks:
  File "C:\Users\arian\AppData\Local\Programs\Python\Python310\lib\site-packages\pip\_internal\cli\progress_bars.py", line 53, in _rich_progress_bar
    for chunk in iterable:
  File "C:\Users\arian\AppData\Local\Programs\Python\Python310\lib\site-packages\pip\_internal\network\utils.py", line 63, in response_chunks
    for chunk in response.raw.stream(
  File "C:\Users\arian\AppData\Local\Programs\Python\Python310\lib\site-packages\pip\_vendor\urllib3\response.py", line 573, in stream
    data = self.read(amt=amt, decode_content=decode_content)
  File "C:\Users\arian\AppData\Local\Programs\Python\Python310\lib\site-packages\pip\_vendor\urllib3\response.py", line 509, in read
    with self._error_catcher():
  File "C:\Users\arian\AppData\Local\Programs\Python\Python310\lib\contextlib.py", line 153, in __exit__
    self.gen.throw(typ, value, traceback)
  File "C:\Users\arian\AppData\Local\Programs\Python\Python310\lib\site-packages\pip\_vendor\urllib3\response.py", line 446, in _error_catcher
    raise SSLError(e)
pip._vendor.urllib3.exceptions.SSLError: [SSL: DECRYPTION_FAILED_OR_BAD_RECORD_MAC] decryption failed or bad record mac (_ssl.c:2548)

[notice] A new release of pip available: 22.1.2 -> 22.3.1
[notice] To update, run: python.exe -m pip install --upgrade pip

C:\Users\arian>pip install -U scikit-learn
Collecting scikit-learn
  Downloading scikit_learn-1.1.3-cp310-cp310-win_amd64.whl (7.5 MB)
     ---------------------------------------- 7.5/7.5 MB 1.8 MB/s eta 0:00:00
Requirement already satisfied: scipy>=1.3.2 in c:\users\arian\appdata\local\programs\python\python310\lib\site-packages (from scikit-learn) (1.9.3)
Collecting threadpoolctl>=2.0.0
  Downloading threadpoolctl-3.1.0-py3-none-any.whl (14 kB)
Collecting joblib>=1.0.0
  Downloading joblib-1.2.0-py3-none-any.whl (297 kB)
     ---------------------------------------- 298.0/298.0 kB 1.7 MB/s eta 0:00:00
Requirement already satisfied: numpy>=1.17.3 in c:\users\arian\appdata\local\programs\python\python310\lib\site-packages (from scikit-learn) (1.23.5)
Installing collected packages: threadpoolctl, joblib, scikit-learn
Successfully installed joblib-1.2.0 scikit-learn-1.1.3 threadpoolctl-3.1.0

[notice] A new release of pip available: 22.1.2 -> 22.3.1
[notice] To update, run: python.exe -m pip install --upgrade pip

C:\Users\arian>pip install tensorflow
Collecting tensorflow
  Downloading tensorflow-2.11.0-cp310-cp310-win_amd64.whl (1.9 kB)
Collecting tensorflow-intel==2.11.0
  Downloading tensorflow_intel-2.11.0-cp310-cp310-win_amd64.whl (266.3 MB)
     ---------------------------- ----------- 191.7/266.3 MB 1.6 MB/s eta 0:00:47
ERROR: Exception:
Traceback (most recent call last):
  File "C:\Users\arian\AppData\Local\Programs\Python\Python310\lib\site-packages\pip\_vendor\urllib3\response.py", line 435, in _error_catcher
    yield
  File "C:\Users\arian\AppData\Local\Programs\Python\Python310\lib\site-packages\pip\_vendor\urllib3\response.py", line 516, in read
    data = self._fp.read(amt) if not fp_closed else b""
  File "C:\Users\arian\AppData\Local\Programs\Python\Python310\lib\site-packages\pip\_vendor\cachecontrol\filewrapper.py", line 90, in read
    data = self.__fp.read(amt)
  File "C:\Users\arian\AppData\Local\Programs\Python\Python310\lib\http\client.py", line 465, in read
    s = self.fp.read(amt)
  File "C:\Users\arian\AppData\Local\Programs\Python\Python310\lib\socket.py", line 705, in readinto
    return self._sock.recv_into(b)
  File "C:\Users\arian\AppData\Local\Programs\Python\Python310\lib\ssl.py", line 1273, in recv_into
    return self.read(nbytes, buffer)
  File "C:\Users\arian\AppData\Local\Programs\Python\Python310\lib\ssl.py", line 1129, in read
    return self._sslobj.read(len, buffer)
ssl.SSLError: [SSL: DECRYPTION_FAILED_OR_BAD_RECORD_MAC] decryption failed or bad record mac (_ssl.c:2548)

During handling of the above exception, another exception occurred:

Traceback (most recent call last):
  File "C:\Users\arian\AppData\Local\Programs\Python\Python310\lib\site-packages\pip\_internal\cli\base_command.py", line 167, in exc_logging_wrapper
    status = run_func(*args)
  File "C:\Users\arian\AppData\Local\Programs\Python\Python310\lib\site-packages\pip\_internal\cli\req_command.py", line 205, in wrapper
    return func(self, options, args)
  File "C:\Users\arian\AppData\Local\Programs\Python\Python310\lib\site-packages\pip\_internal\commands\install.py", line 341, in run
    requirement_set = resolver.resolve(
  File "C:\Users\arian\AppData\Local\Programs\Python\Python310\lib\site-packages\pip\_internal\resolution\resolvelib\resolver.py", line 94, in resolve
    result = self._result = resolver.resolve(
  File "C:\Users\arian\AppData\Local\Programs\Python\Python310\lib\site-packages\pip\_vendor\resolvelib\resolvers.py", line 481, in resolve
    state = resolution.resolve(requirements, max_rounds=max_rounds)
  File "C:\Users\arian\AppData\Local\Programs\Python\Python310\lib\site-packages\pip\_vendor\resolvelib\resolvers.py", line 373, in resolve
    failure_causes = self._attempt_to_pin_criterion(name)
  File "C:\Users\arian\AppData\Local\Programs\Python\Python310\lib\site-packages\pip\_vendor\resolvelib\resolvers.py", line 213, in _attempt_to_pin_criterion
    criteria = self._get_updated_criteria(candidate)
  File "C:\Users\arian\AppData\Local\Programs\Python\Python310\lib\site-packages\pip\_vendor\resolvelib\resolvers.py", line 204, in _get_updated_criteria
    self._add_to_criteria(criteria, requirement, parent=candidate)
  File "C:\Users\arian\AppData\Local\Programs\Python\Python310\lib\site-packages\pip\_vendor\resolvelib\resolvers.py", line 172, in _add_to_criteria
    if not criterion.candidates:
  File "C:\Users\arian\AppData\Local\Programs\Python\Python310\lib\site-packages\pip\_vendor\resolvelib\structs.py", line 151, in __bool__
    return bool(self._sequence)
  File "C:\Users\arian\AppData\Local\Programs\Python\Python310\lib\site-packages\pip\_internal\resolution\resolvelib\found_candidates.py", line 155, in __bool__
    return any(self)
  File "C:\Users\arian\AppData\Local\Programs\Python\Python310\lib\site-packages\pip\_internal\resolution\resolvelib\found_candidates.py", line 143, in <genexpr>
    return (c for c in iterator if id(c) not in self._incompatible_ids)
  File "C:\Users\arian\AppData\Local\Programs\Python\Python310\lib\site-packages\pip\_internal\resolution\resolvelib\found_candidates.py", line 47, in _iter_built
    candidate = func()
  File "C:\Users\arian\AppData\Local\Programs\Python\Python310\lib\site-packages\pip\_internal\resolution\resolvelib\factory.py", line 215, in _make_candidate_from_link
    self._link_candidate_cache[link] = LinkCandidate(
  File "C:\Users\arian\AppData\Local\Programs\Python\Python310\lib\site-packages\pip\_internal\resolution\resolvelib\candidates.py", line 291, in __init__
    super().__init__(
  File "C:\Users\arian\AppData\Local\Programs\Python\Python310\lib\site-packages\pip\_internal\resolution\resolvelib\candidates.py", line 161, in __init__
    self.dist = self._prepare()
  File "C:\Users\arian\AppData\Local\Programs\Python\Python310\lib\site-packages\pip\_internal\resolution\resolvelib\candidates.py", line 230, in _prepare
    dist = self._prepare_distribution()
  File "C:\Users\arian\AppData\Local\Programs\Python\Python310\lib\site-packages\pip\_internal\resolution\resolvelib\candidates.py", line 302, in _prepare_distribution
    return preparer.prepare_linked_requirement(self._ireq, parallel_builds=True)
  File "C:\Users\arian\AppData\Local\Programs\Python\Python310\lib\site-packages\pip\_internal\operations\prepare.py", line 428, in prepare_linked_requirement
    return self._prepare_linked_requirement(req, parallel_builds)
  File "C:\Users\arian\AppData\Local\Programs\Python\Python310\lib\site-packages\pip\_internal\operations\prepare.py", line 473, in _prepare_linked_requirement
    local_file = unpack_url(
  File "C:\Users\arian\AppData\Local\Programs\Python\Python310\lib\site-packages\pip\_internal\operations\prepare.py", line 155, in unpack_url
    file = get_http_url(
  File "C:\Users\arian\AppData\Local\Programs\Python\Python310\lib\site-packages\pip\_internal\operations\prepare.py", line 96, in get_http_url
    from_path, content_type = download(link, temp_dir.path)
  File "C:\Users\arian\AppData\Local\Programs\Python\Python310\lib\site-packages\pip\_internal\network\download.py", line 146, in __call__
    for chunk in chunks:
  File "C:\Users\arian\AppData\Local\Programs\Python\Python310\lib\site-packages\pip\_internal\cli\progress_bars.py", line 53, in _rich_progress_bar
    for chunk in iterable:
  File "C:\Users\arian\AppData\Local\Programs\Python\Python310\lib\site-packages\pip\_internal\network\utils.py", line 63, in response_chunks
    for chunk in response.raw.stream(
  File "C:\Users\arian\AppData\Local\Programs\Python\Python310\lib\site-packages\pip\_vendor\urllib3\response.py", line 573, in stream
    data = self.read(amt=amt, decode_content=decode_content)
  File "C:\Users\arian\AppData\Local\Programs\Python\Python310\lib\site-packages\pip\_vendor\urllib3\response.py", line 509, in read
    with self._error_catcher():
  File "C:\Users\arian\AppData\Local\Programs\Python\Python310\lib\contextlib.py", line 153, in __exit__
    self.gen.throw(typ, value, traceback)
  File "C:\Users\arian\AppData\Local\Programs\Python\Python310\lib\site-packages\pip\_vendor\urllib3\response.py", line 446, in _error_catcher
    raise SSLError(e)
pip._vendor.urllib3.exceptions.SSLError: [SSL: DECRYPTION_FAILED_OR_BAD_RECORD_MAC] decryption failed or bad record mac (_ssl.c:2548)

[notice] A new release of pip available: 22.1.2 -> 22.3.1
[notice] To update, run: python.exe -m pip install --upgrade pip
